Traceback (most recent call last):
  File "/Users/sienzhao/opt/anaconda3/lib/python3.8/site-packages/jupyter_cache/executors/utils.py", line 51, in single_nb_execution
    executenb(
  File "/Users/sienzhao/opt/anaconda3/lib/python3.8/site-packages/nbclient/client.py", line 1087, in execute
    return NotebookClient(nb=nb, resources=resources, km=km, **kwargs).execute()
  File "/Users/sienzhao/opt/anaconda3/lib/python3.8/site-packages/nbclient/util.py", line 74, in wrapped
    return just_run(coro(*args, **kwargs))
  File "/Users/sienzhao/opt/anaconda3/lib/python3.8/site-packages/nbclient/util.py", line 53, in just_run
    return loop.run_until_complete(coro)
  File "/Users/sienzhao/opt/anaconda3/lib/python3.8/asyncio/base_events.py", line 616, in run_until_complete
    return future.result()
  File "/Users/sienzhao/opt/anaconda3/lib/python3.8/site-packages/nbclient/client.py", line 540, in async_execute
    await self.async_execute_cell(
  File "/Users/sienzhao/opt/anaconda3/lib/python3.8/site-packages/nbclient/client.py", line 832, in async_execute_cell
    self._check_raise_for_error(cell, exec_reply)
  File "/Users/sienzhao/opt/anaconda3/lib/python3.8/site-packages/nbclient/client.py", line 740, in _check_raise_for_error
    raise CellExecutionError.from_cell_and_msg(cell, exec_reply['content'])
nbclient.exceptions.CellExecutionError: An error occurred while executing the following cell:
------------------
# packages
import pandas as pd
import numpy as np
from src.model import solve_hjb_y, solve_hjb_y_jump, solve_baseline, minimize_g, minimize_Ï€
from src.utilities import find_nearest_value, solve_post_jump
from src.simulation import simulate_me
from IPython.display import IFrame
import plotly.io as pio
import plotly.graph_objects as go
from plotly.subplots import make_subplots
import plotly.offline as pyo
import pickle
pyo.init_notebook_mode()
------------------

[0;31m---------------------------------------------------------------------------[0m
[0;31mImportError[0m                               Traceback (most recent call last)
[0;32m<ipython-input-1-0297f214e0cc>[0m in [0;36m<module>[0;34m[0m
[1;32m      2[0m [0;32mimport[0m [0mpandas[0m [0;32mas[0m [0mpd[0m[0;34m[0m[0;34m[0m[0m
[1;32m      3[0m [0;32mimport[0m [0mnumpy[0m [0;32mas[0m [0mnp[0m[0;34m[0m[0;34m[0m[0m
[0;32m----> 4[0;31m [0;32mfrom[0m [0msrc[0m[0;34m.[0m[0mmodel[0m [0;32mimport[0m [0msolve_hjb_y[0m[0;34m,[0m [0msolve_hjb_y_jump[0m[0;34m,[0m [0msolve_baseline[0m[0;34m,[0m [0mminimize_g[0m[0;34m,[0m [0mminimize_Ï€[0m[0;34m[0m[0;34m[0m[0m
[0m[1;32m      5[0m [0;32mfrom[0m [0msrc[0m[0;34m.[0m[0mutilities[0m [0;32mimport[0m [0mfind_nearest_value[0m[0;34m,[0m [0msolve_post_jump[0m[0;34m[0m[0;34m[0m[0m
[1;32m      6[0m [0;32mfrom[0m [0msrc[0m[0;34m.[0m[0msimulation[0m [0;32mimport[0m [0msimulate_me[0m[0;34m[0m[0;34m[0m[0m

[0;32m~/Documents/GitHub/ClimateUncertaintySpillover/climateuncertaintyspilloverbook/src/model.py[0m in [0;36m<module>[0;34m[0m
[1;32m      5[0m """
[1;32m      6[0m [0;32mimport[0m [0mnumpy[0m [0;32mas[0m [0mnp[0m[0;34m[0m[0;34m[0m[0m
[0;32m----> 7[0;31m [0;32mfrom[0m [0;34m.[0m[0mutilities[0m [0;32mimport[0m [0mcompute_derivatives[0m[0;34m,[0m [0mJ[0m[0;34m[0m[0;34m[0m[0m
[0m[1;32m      8[0m [0;32mfrom[0m [0;34m.[0m[0msolver[0m [0;32mimport[0m [0mfalse_transient[0m[0;34m[0m[0;34m[0m[0m
[1;32m      9[0m [0;34m[0m[0m

[0;32m~/Documents/GitHub/ClimateUncertaintySpillover/climateuncertaintyspilloverbook/src/utilities.py[0m in [0;36m<module>[0;34m[0m
[1;32m      4[0m """
[1;32m      5[0m [0;32mimport[0m [0mnumpy[0m [0;32mas[0m [0mnp[0m[0;34m[0m[0;34m[0m[0m
[0;32m----> 6[0;31m [0;32mfrom[0m [0mnumba[0m [0;32mimport[0m [0mnjit[0m[0;34m[0m[0;34m[0m[0m
[0m[1;32m      7[0m [0;32mfrom[0m [0mmultiprocessing[0m [0;32mimport[0m [0mPool[0m[0;34m[0m[0;34m[0m[0m
[1;32m      8[0m [0;34m[0m[0m

[0;31mImportError[0m: cannot import name 'njit' from 'numba' (unknown location)
ImportError: cannot import name 'njit' from 'numba' (unknown location)

